Workbook
Name Currency_name: [1]Input!$D$24

Sheet Title
C15: Финансово-экономическая модель
B16: =IF(C16="","Название проекта:","") | C16: Строительство производства сухих строительных смесей
D18: Ввводные данные
C19: Link 1 | D19: Ссылка
C20: Calculate | D20: Расчет
C21: Other | D21: Изменение формулы
D22: Техническая ячейка
C26: Автор: Баринова К.О.

Sheet Input
A1: =Title!$C$16 -> Строительство производства сухих строительных смесей
A2: =Title!$C$15 -> Финансово-экономическая модель | L2: =DATE(($H$9),1,1) -> 45292 | M2: =IFERROR(IF(YEAR(L3)<YEAR(EDATE($H$12,$H$13*12)-1),L3+1,""),"") -> 45658 | N2: =IFERROR(IF(YEAR(M3)<YEAR(EDATE($H$12,$H$13*12)-1),M3+1,""),"") -> 46023 | O2: =IFERROR(IF(YEAR(N3)<YEAR(EDATE($H$12,$H$13*12)-1),N3+1,""),"") -> 46388 | P2: =IFERROR(IF(YEAR(O3)<YEAR(EDATE($H$12,$H$13*12)-1),O3+1,""),"") -> 46753 | Q2: =IFERROR(IF(YEAR(P3)<YEAR(EDATE($H$12,$H$13*12)-1),P3+1,""),"") -> 47119 | R2: =IFERROR(IF(YEAR(Q3)<YEAR(EDATE($H$12,$H$13*12)-1),Q3+1,""),"") -> 47484 | S2: =IFERROR(IF(YEAR(R3)<YEAR(EDATE($H$12,$H$13*12)-1),R3+1,""),"") -> 47849 | T2: =IFERROR(IF(YEAR(S3)<YEAR(EDATE($H$12,$H$13*12)-1),S3+1,""),"") -> 48214 | ... AN2: =IFERROR(IF(YEAR(AM3)<YEAR(EDATE($H$12,$H$13*12)-1),AM3+1,""),"")
A3: Входные данные | L3: =DATE(YEAR(L2),12,31) -> 45657 | M3: =IFERROR(DATE(YEAR(M2),12,31),"") -> 46022 | N3: =IFERROR(DATE(YEAR(N2),12,31),"") -> 46387 | O3: =IFERROR(DATE(YEAR(O2),12,31),"") -> 46752 | P3: =IFERROR(DATE(YEAR(P2),12,31),"") -> 47118 | Q3: =IFERROR(DATE(YEAR(Q2),12,31),"") -> 47483 | R3: =IFERROR(DATE(YEAR(R2),12,31),"") -> 47848 | S3: =IFERROR(DATE(YEAR(S2),12,31),"") -> 48213 | T3: =IFERROR(DATE(YEAR(T2),12,31),"") -> 48579 | ... AN3: =IFERROR(DATE(YEAR(AN2),12,31),"")
L4: =IFERROR(IF(YEAR(L3)<YEAR($H$10),"Факт","Прогноз"),"") -> Факт | M4: =IFERROR(IF(YEAR(M3)<YEAR($H$10),"Факт","Прогноз"),"") -> Прогноз | N4: =IFERROR(IF(YEAR(N3)<YEAR($H$10),"Факт","Прогноз"),"") -> Прогноз | O4: =IFERROR(IF(YEAR(O3)<YEAR($H$10),"Факт","Прогноз"),"") -> Прогноз | P4: =IFERROR(IF(YEAR(P3)<YEAR($H$10),"Факт","Прогноз"),"") -> Прогноз | Q4: =IFERROR(IF(YEAR(Q3)<YEAR($H$10),"Факт","Прогноз"),"") -> Прогноз | R4: =IFERROR(IF(YEAR(R3)<YEAR($H$10),"Факт","Прогноз"),"") -> Прогноз | S4: =IFERROR(IF(YEAR(S3)<YEAR($H$10),"Факт","Прогноз"),"") -> Прогноз | ... AN4: =IFERROR(IF(YEAR(AN3)<YEAR($H$10),"Факт","Прогноз"),"")
G5: Ед. измерения | H5: Значение/База | J5: Сумма
B7: ВВОДНЫЕ ВРЕМЕННЫЕ ПАРАМЕТРЫ МОДЕЛИ
B9: Дата начала анализа | G9: дата | H9: 2024
B10: Дата начала прогнозного периода | G10: дата | H10: 45658
B11: Дата начала инвестиционной деятельности | G11: дата | H11: 45658
B12: Дата начала операционной деятельности | G12: дата | H12: 46082
B13: Горизонт планирования | G13: лет | H13: 15 | I13: // не более 29 лет с даты начала анализа
B14: Дата окончания операционной деятельности | G14: дата | H14: =EDATE(H12,H13*12) -> 51561
B15: Базовый год индексации | G15: год | H15: 2024
B16: Дата начала оптимизации состава продукции | G16: дата | H16: 49126
B17: Возмещать НДС из бюджета | G17: х | I17: TRUE
B19: МАКРОЭКОНОМИЧЕСКИЕ ПАРАМЕТРЫ ПРОЕКТА
B21: Обменный курс рубля к доллару | G21: RUB/USD | L21: 59 | M21: 60 | N21: 61 | O21: 62 | P21: 63 | Q21: 59 | R21: 59 | S21: 59 | T21: 59 | U21: 59 | V21: 59 | W21: 59 | X21: 59 | Y21: 59 | Z21: 59 | AA21: 59 | AB21: 59 | AC21: 59
B22: CPI, (RUB) | G22: х | L22: 1.04 | M22: 1.04 | N22: 1.04 | O22: 1.04 | P22: 1.04 | Q22: 1.04 | R22: 1.04 | S22: 1.04 | T22: 1.04 | U22: 1.04 | V22: 1.04 | W22: 1.04 | X22: 1.04 | Y22: 1.04 | Z22: 1.04 | AA22: 1.04 | AB22: 1.04 | AC22: 1.04
B23: PPI, (RUB) | G23: х | L23: 1.04 | M23: 1.04 | N23: 1.04 | O23: 1.04 | P23: 1.04 | Q23: 1.04 | R23: 1.04 | S23: 1.04 | T23: 1.04 | U23: 1.04 | V23: 1.04 | W23: 1.04 | X23: 1.04 | Y23: 1.04 | Z23: 1.04 | AA23: 1.04 | AB23: 1.04 | AC23: 1.04
B24: PPI, (USD) | G24: х | L24: 1.03 | M24: 1.03 | N24: 1.03 | O24: 1.03 | P24: 1.03 | Q24: 1.03 | R24: 1.03 | S24: 1.03 | T24: 1.03 | U24: 1.03 | V24: 1.03 | W24: 1.03 | X24: 1.03 | Y24: 1.03 | Z24: 1.03 | AA24: 1.03 | AB24: 1.03 | AC24: 1.03
B25: Индекс роста заработной платы (RUB) | G25: х | L25: 1.04 | M25: 1.04 | N25: 1.04 | O25: 1.04 | P25: 1.04 | Q25: 1.04 | R25: 1.04 | S25: 1.04 | T25: 1.04 | U25: 1.04 | V25: 1.04 | W25: 1.04 | X25: 1.04 | Y25: 1.04 | Z25: 1.04 | AA25: 1.04 | AB25: 1.04 | AC25: 1.04
B26: Индекс роста цен на естественные монополии (электроэнергия) | G26: х | L26: 1.05 | M26: 1.05 | N26: 1.05 | O26: 1.05 | P26: 1.05 | Q26: 1.05 | R26: 1.05 | S26: 1.05 | T26: 1.05 | U26: 1.05 | V26: 1.05 | W26: 1.05 | X26: 1.05 | Y26: 1.05 | Z26: 1.05 | AA26: 1.05 | AB26: 1.05 | AC26: 1.05
B27: Ключевая ставка ЦБ РФ | G27: % | L27: 0.21 | M27: 0.2 | N27: 0.15 | O27: 0.11 | P27: 0.1 | Q27: 0.08 | R27: 0.07 | S27: 0.07 | T27: 0.07 | U27: 0.07 | V27: 0.07 | W27: 0.07 | X27: 0.07 | Y27: 0.07 | Z27: 0.07 | AA27: 0.07 | AB27: 0.07 | AC27: 0.07
B29: НАЛОГОВОЕ ОКРУЖЕНИЕ ПРОЕКТА
B31: Доля прибыли к зачету против убытков | G31: % | L31: 0.5 | M31: 0.5 | N31: 0.5 | O31: 0.5 | P31: 0.5 | Q31: 0.5 | R31: 0.5 | S31: 0.5 | T31: 0.5 | U31: 0.5 | V31: 0.5 | W31: 0.5 | X31: 0.5 | Y31: 0.5 | Z31: 0.5 | AA31: 0.5 | AB31: 0.5 | AC31: 0.5
B32: НДС | G32: % | L32: 0.2 | M32: 0.2 | N32: 0.2 | O32: 0.2 | P32: 0.2 | Q32: 0.2 | R32: 0.2 | S32: 0.2 | T32: 0.2 | U32: 0.2 | V32: 0.2 | W32: 0.2 | X32: 0.2 | Y32: 0.2 | Z32: 0.2 | AA32: 0.2 | AB32: 0.2 | AC32: 0.2
B33: Ставка налога на прибыль | G33: % | L33: 0.2 | M33: 0.25 | N33: 0.25 | O33: 0.25 | P33: 0.25 | Q33: 0.25 | R33: 0.25 | S33: 0.25 | T33: 0.25 | U33: 0.25 | V33: 0.25 | W33: 0.25 | X33: 0.25 | Y33: 0.25 | Z33: 0.25 | AA33: 0.25 | AB33: 0.25 | AC33: 0.25
B34: Ставка налога на имущество | G34: % | L34: 0.022 | M34: 0.022 | N34: 0.022 | O34: 0.022 | P34: 0.022 | Q34: 0.022 | R34: 0.022 | S34: 0.022 | T34: 0.022 | U34: 0.022 | V34: 0.022 | W34: 0.022 | X34: 0.022 | Y34: 0.022 | Z34: 0.022 | AA34: 0.022 | AB34: 0.022 | AC34: 0.022
B35: Ставка налога на землю | G35: % | L35: 0.015 | M35: 0.015 | N35: 0.015 | O35: 0.015 | P35: 0.015 | Q35: 0.015 | R35: 0.015 | S35: 0.015 | T35: 0.015 | U35: 0.015 | V35: 0.015 | W35: 0.015 | X35: 0.015 | Y35: 0.015 | Z35: 0.015 | AA35: 0.015 | AB35: 0.015 | AC35: 0.015
B36: Ставка транспортного налога | G36: руб./л.с. | L36: 2.5 | M36: 2.5 | N36: 2.5 | O36: 2.5 | P36: 2.5 | Q36: 2.5 | R36: 2.5 | S36: 2.5 | T36: 2.5 | U36: 2.5 | V36: 2.5 | W36: 2.5 | X36: 2.5 | Y36: 2.5 | Z36: 2.5 | AA36: 2.5 | AB36: 2.5 | AC36: 2.5
B37: Социальные отчисления (ПФР, ФСС, ФОМС) | G37: % | L37: 0.302 | M37: 0.302 | N37: 0.302 | O37: 0.302 | P37: 0.302 | Q37: 0.302 | R37: 0.302 | S37: 0.302 | T37: 0.302 | U37: 0.302 | V37: 0.302 | W37: 0.302 | X37: 0.302 | Y37: 0.302 | Z37: 0.302 | AA37: 0.302 | AB37: 0.302 | AC37: 0.302
B38: Социальные отчисления от несчастных случаев и проф. заболеваний (рабочие) | G38: % | L38: 0.08 | M38: 0.08 | N38: 0.08 | O38: 0.08 | P38: 0.08 | Q38: 0.08 | R38: 0.08 | S38: 0.08 | T38: 0.08 | U38: 0.08 | V38: 0.08 | W38: 0.08 | X38: 0.08 | Y38: 0.08 | Z38: 0.08 | AA38: 0.08 | AB38: 0.08 | AC38: 0.08
B39: Социальные отчисления от несчастных случаев и проф. заболеваний (служащие) | G39: % | L39: 0.05 | M39: 0.05 | N39: 0.05 | O39: 0.05 | P39: 0.05 | Q39: 0.05 | R39: 0.05 | S39: 0.05 | T39: 0.05 | U39: 0.05 | V39: 0.05 | W39: 0.05 | X39: 0.05 | Y39: 0.05 | Z39: 0.05 | AA39: 0.05 | AB39: 0.05 | AC39: 0.05
B41: КАПИТАЛЬНЫЕ И ПОДДЕРЖИВАЮЩИЕ ВЛОЖЕНИЯ
B43: Общие капитальные вложения проекта, без НДС | G43: млн руб. | H43: 215
B45: Доля импорта (оборудование) | G45: % | H45: 0.3
B47: Доля импорта (транспорт) | G47: % | H47: 0.3
B49: Доля недвижимого имущества (от общей стоимости зданий, сооружений, оборудования) | G49: % | H49: 0.5
B51: Капитальные вложения разбивка по направлениям
C52: Земля | G52: % | H52: 0
...

Sheet Расчеты
B1: =Title!$C$16 -> Строительство производства сухих строительных смесей
B2: =Title!$C$15 -> Финансово-экономическая модель | L2: {=Input!L2:L4} -> 45292 | M2: {=Input!M2:M4} -> 45658 | N2: {=Input!N2:N4} -> 46023 | O2: {=Input!O2:O4} -> 46388 | P2: {=Input!P2:P4} -> 46753 | Q2: {=Input!Q2:Q4} -> 47119 | R2: {=Input!R2:R4} -> 47484 | S2: {=Input!S2:S4} -> 47849 | ... AN2: {=Input!AN2:AN4}
B3: Расчеты | L3: 45657 | M3: 46022 | N3: 46387 | O3: 46752 | P3: 47118 | Q3: 47483 | R3: 47848 | S3: 48213 | T3: 48579 | U3: 48944 | V3: 49309 | W3: 49674 | X3: 50040 | Y3: 50405 | Z3: 50770 | AA3: 51135 | AB3: 51501 | AC3: 51866
L4: Факт | M4: Прогноз | N4: Прогноз | O4: Прогноз | P4: Прогноз | Q4: Прогноз | R4: Прогноз | S4: Прогноз | T4: Прогноз | U4: Прогноз | V4: Прогноз | W4: Прогноз | X4: Прогноз | Y4: Прогноз | Z4: Прогноз | AA4: Прогноз | AB4: Прогноз | AC4: Прогноз
H5: Ед. измерения | I5: Значение/База/Сумма
C7: ВРЕМЕННЫЕ ПАРАМЕТРЫ ПРОЕКТА
C9: Год | H9: х | L9: =IFERROR(YEAR(L3),"") -> 2024 | M9: =IFERROR(YEAR(M3),"") -> 2025 | N9: =IFERROR(YEAR(N3),"") -> 2026 | O9: =IFERROR(YEAR(O3),"") -> 2027 | P9: =IFERROR(YEAR(P3),"") -> 2028 | Q9: =IFERROR(YEAR(Q3),"") -> 2029 | R9: =IFERROR(YEAR(R3),"") -> 2030 | S9: =IFERROR(YEAR(S3),"") -> 2031 | ... AN9: =IFERROR(YEAR(AN3),"")
C10: Индекс операционной деятельности | H10: х | L10: =IF(L9=YEAR(Input!$H$12),YEARFRAC(Input!$H$12,Расчеты!L3),IF(Расчеты!L9=YEAR(Input!$H$14),YEARFRAC(Расчеты!L2,Input!$H$14),IF(AND(Расчеты!L9>YEAR(Input!$H$12),Расчеты!L9<YEAR(Input!$H$14)),1,0))) -> 0 | M10: =IF(M9=YEAR(Input!$H$12),YEARFRAC(Input!$H$12,Расчеты!M3),IF(Расчеты!M9=YEAR(Input!$H$14),YEARFRAC(Расчеты!M2,Input!$H$14),IF(AND(Расчеты!M9>YEAR(Input!$H$12),Расчеты!M9<YEAR(Input!$H$14)),1,0))) -> 0 | N10: =IF(N9=YEAR(Input!$H$12),YEARFRAC(Input!$H$12,Расчеты!N3),IF(Расчеты!N9=YEAR(Input!$H$14),YEARFRAC(Расчеты!N2,Input!$H$14),IF(AND(Расчеты!N9>YEAR(Input!$H$12),Расчеты!N9<YEAR(Input!$H$14)),1,0))) -> 0.83333333 | O10: =IF(O9=YEAR(Input!$H$12),YEARFRAC(Input!$H$12,Расчеты!O3),IF(Расчеты!O9=YEAR(Input!$H$14),YEARFRAC(Расчеты!O2,Input!$H$14),IF(AND(Расчеты!O9>YEAR(Input!$H$12),Расчеты!O9<YEAR(Input!$H$14)),1,0))) -> 1 | P10: =IF(P9=YEAR(Input!$H$12),YEARFRAC(Input!$H$12,Расчеты!P3),IF(Расчеты!P9=YEAR(Input!$H$14),YEARFRAC(Расчеты!P2,Input!$H$14),IF(AND(Расчеты!P9>YEAR(Input!$H$12),Расчеты!P9<YEAR(Input!$H$14)),1,0))) -> 1 | Q10: =IF(Q9=YEAR(Input!$H$12),YEARFRAC(Input!$H$12,Расчеты!Q3),IF(Расчеты!Q9=YEAR(Input!$H$14),YEARFRAC(Расчеты!Q2,Input!$H$14),IF(AND(Расчеты!Q9>YEAR(Input!$H$12),Расчеты!Q9<YEAR(Input!$H$14)),1,0))) -> 1 | R10: =IF(R9=YEAR(Input!$H$12),YEARFRAC(Input!$H$12,Расчеты!R3),IF(Расчеты!R9=YEAR(Input!$H$14),YEARFRAC(Расчеты!R2,Input!$H$14),IF(AND(Расчеты!R9>YEAR(Input!$H$12),Расчеты!R9<YEAR(Input!$H$14)),1,0))) -> 1 | S10: =IF(S9=YEAR(Input!$H$12),YEARFRAC(Input!$H$12,Расчеты!S3),IF(Расчеты!S9=YEAR(Input!$H$14),YEARFRAC(Расчеты!S2,Input!$H$14),IF(AND(Расчеты!S9>YEAR(Input!$H$12),Расчеты!S9<YEAR(Input!$H$14)),1,0))) -> 1 | ... AN10: =IF(AN9=YEAR(Input!$H$12),YEARFRAC(Input!$H$12,Расчеты!AN3),IF(Расчеты!AN9=YEAR(Input!$H$14),YEARFRAC(Расчеты!AN2,Input!$H$14),IF(AND(Расчеты!AN9>YEAR(Input!$H$12),Расчеты!AN9<YEAR(Input!$H$14)),1,0))) -> 0
C11: Количество месяцев операционной деятельности | H11: х | L11: =L10*12 -> 0 | M11: =M10*12 -> 0 | N11: =N10*12 -> 10 | O11: =O10*12 -> 12 | P11: =P10*12 -> 12 | Q11: =Q10*12 -> 12 | R11: =R10*12 -> 12 | S11: =S10*12 -> 12 | ... AN11: =AN10*12 -> 0
C12: Индекс операционной деятельности после оптимизации состава продукции | H12: х | L12: =IF(L9=YEAR(Input!$H$16),YEARFRAC(Input!$H$16,Расчеты!L3),IF(Расчеты!L9=YEAR(Input!$H$14),1,IF(AND(Расчеты!L9>YEAR(Input!$H$16),Расчеты!L9<YEAR(Input!$H$14)),1,0))) -> 0 | M12: =IF(M9=YEAR(Input!$H$16),YEARFRAC(Input!$H$16,Расчеты!M3),IF(Расчеты!M9=YEAR(Input!$H$14),1,IF(AND(Расчеты!M9>YEAR(Input!$H$16),Расчеты!M9<YEAR(Input!$H$14)),1,0))) -> 0 | N12: =IF(N9=YEAR(Input!$H$16),YEARFRAC(Input!$H$16,Расчеты!N3),IF(Расчеты!N9=YEAR(Input!$H$14),1,IF(AND(Расчеты!N9>YEAR(Input!$H$16),Расчеты!N9<YEAR(Input!$H$14)),1,0))) -> 0 | O12: =IF(O9=YEAR(Input!$H$16),YEARFRAC(Input!$H$16,Расчеты!O3),IF(Расчеты!O9=YEAR(Input!$H$14),1,IF(AND(Расчеты!O9>YEAR(Input!$H$16),Расчеты!O9<YEAR(Input!$H$14)),1,0))) -> 0 | P12: =IF(P9=YEAR(Input!$H$16),YEARFRAC(Input!$H$16,Расчеты!P3),IF(Расчеты!P9=YEAR(Input!$H$14),1,IF(AND(Расчеты!P9>YEAR(Input!$H$16),Расчеты!P9<YEAR(Input!$H$14)),1,0))) -> 0 | Q12: =IF(Q9=YEAR(Input!$H$16),YEARFRAC(Input!$H$16,Расчеты!Q3),IF(Расчеты!Q9=YEAR(Input!$H$14),1,IF(AND(Расчеты!Q9>YEAR(Input!$H$16),Расчеты!Q9<YEAR(Input!$H$14)),1,0))) -> 0 | R12: =IF(R9=YEAR(Input!$H$16),YEARFRAC(Input!$H$16,Расчеты!R3),IF(Расчеты!R9=YEAR(Input!$H$14),1,IF(AND(Расчеты!R9>YEAR(Input!$H$16),Расчеты!R9<YEAR(Input!$H$14)),1,0))) -> 0 | S12: =IF(S9=YEAR(Input!$H$16),YEARFRAC(Input!$H$16,Расчеты!S3),IF(Расчеты!S9=YEAR(Input!$H$14),1,IF(AND(Расчеты!S9>YEAR(Input!$H$16),Расчеты!S9<YEAR(Input!$H$14)),1,0))) -> 0 | ... AN12: =IF(AN9=YEAR(Input!$H$16),YEARFRAC(Input!$H$16,Расчеты!AN3),IF(Расчеты!AN9=YEAR(Input!$H$14),1,IF(AND(Расчеты!AN9>YEAR(Input!$H$16),Расчеты!AN9<YEAR(Input!$H$14)),1,0))) -> 0
C13: Индекс операционной деятельности до оптимизации состава продукции | H13: х | L13: =IF(AND(L9>=YEAR(Input!$H$12),L9<YEAR(Input!$H$16)),1,IF(L9=YEAR(Input!$H$16),YEARFRAC(Расчеты!L2,Input!$H$16,3),0)) -> 0 | M13: =IF(AND(M9>=YEAR(Input!$H$12),M9<YEAR(Input!$H$16)),1,IF(M9=YEAR(Input!$H$16),YEARFRAC(Расчеты!M2,Input!$H$16,3),0)) -> 0 | N13: =IF(AND(N9>=YEAR(Input!$H$12),N9<YEAR(Input!$H$16)),1,IF(N9=YEAR(Input!$H$16),YEARFRAC(Расчеты!N2,Input!$H$16,3),0)) -> 1 | O13: =IF(AND(O9>=YEAR(Input!$H$12),O9<YEAR(Input!$H$16)),1,IF(O9=YEAR(Input!$H$16),YEARFRAC(Расчеты!O2,Input!$H$16,3),0)) -> 1 | P13: =IF(AND(P9>=YEAR(Input!$H$12),P9<YEAR(Input!$H$16)),1,IF(P9=YEAR(Input!$H$16),YEARFRAC(Расчеты!P2,Input!$H$16,3),0)) -> 1 | Q13: =IF(AND(Q9>=YEAR(Input!$H$12),Q9<YEAR(Input!$H$16)),1,IF(Q9=YEAR(Input!$H$16),YEARFRAC(Расчеты!Q2,Input!$H$16,3),0)) -> 1 | R13: =IF(AND(R9>=YEAR(Input!$H$12),R9<YEAR(Input!$H$16)),1,IF(R9=YEAR(Input!$H$16),YEARFRAC(Расчеты!R2,Input!$H$16,3),0)) -> 1 | S13: =IF(AND(S9>=YEAR(Input!$H$12),S9<YEAR(Input!$H$16)),1,IF(S9=YEAR(Input!$H$16),YEARFRAC(Расчеты!S2,Input!$H$16,3),0)) -> 1 | ... AN13: =IF(AND(AN9>=YEAR(Input!$H$12),AN9<YEAR(Input!$H$16)),1,IF(AN9=YEAR(Input!$H$16),YEARFRAC(Расчеты!AN2,Input!$H$16,3),0)) -> 0
C14: Количество дней в году | H14: х | L14: =IFERROR(L3-L2+1,"") -> 366 | M14: =IFERROR(M3-M2+1,"") -> 365 | N14: =IFERROR(N3-N2+1,"") -> 365 | O14: =IFERROR(O3-O2+1,"") -> 365 | P14: =IFERROR(P3-P2+1,"") -> 366 | Q14: =IFERROR(Q3-Q2+1,"") -> 365 | R14: =IFERROR(R3-R2+1,"") -> 365 | S14: =IFERROR(S3-S2+1,"") -> 365 | ... AN14: =IFERROR(AN3-AN2+1,"")
C15: Количество часов в году | H15: х | L15: =IFERROR(L14*24,"") -> 8784 | M15: =IFERROR(M14*24,"") -> 8760 | N15: =IFERROR(N14*24,"") -> 8760 | O15: =IFERROR(O14*24,"") -> 8760 | P15: =IFERROR(P14*24,"") -> 8784 | Q15: =IFERROR(Q14*24,"") -> 8760 | R15: =IFERROR(R14*24,"") -> 8760 | S15: =IFERROR(S14*24,"") -> 8760 | ... AN15: =IFERROR(AN14*24,"")
C16: Количество лет операционной деятельности | H16: х | L16: =IF(L9=YEAR(Input!$H$12),1,IF(AND(Расчеты!L9>YEAR(Input!$H$12),Расчеты!L9<=YEAR(Input!$H$14)),Расчеты!K16+1,0)) -> 0 | M16: =IF(M9=YEAR(Input!$H$12),1,IF(AND(Расчеты!M9>YEAR(Input!$H$12),Расчеты!M9<=YEAR(Input!$H$14)),Расчеты!L16+1,0)) -> 0 | N16: =IF(N9=YEAR(Input!$H$12),1,IF(AND(Расчеты!N9>YEAR(Input!$H$12),Расчеты!N9<=YEAR(Input!$H$14)),Расчеты!M16+1,0)) -> 1 | O16: =IF(O9=YEAR(Input!$H$12),1,IF(AND(Расчеты!O9>YEAR(Input!$H$12),Расчеты!O9<=YEAR(Input!$H$14)),Расчеты!N16+1,0)) -> 2 | P16: =IF(P9=YEAR(Input!$H$12),1,IF(AND(Расчеты!P9>YEAR(Input!$H$12),Расчеты!P9<=YEAR(Input!$H$14)),Расчеты!O16+1,0)) -> 3 | Q16: =IF(Q9=YEAR(Input!$H$12),1,IF(AND(Расчеты!Q9>YEAR(Input!$H$12),Расчеты!Q9<=YEAR(Input!$H$14)),Расчеты!P16+1,0)) -> 4 | R16: =IF(R9=YEAR(Input!$H$12),1,IF(AND(Расчеты!R9>YEAR(Input!$H$12),Расчеты!R9<=YEAR(Input!$H$14)),Расчеты!Q16+1,0)) -> 5 | S16: =IF(S9=YEAR(Input!$H$12),1,IF(AND(Расчеты!S9>YEAR(Input!$H$12),Расчеты!S9<=YEAR(Input!$H$14)),Расчеты!R16+1,0)) -> 6 | ... AN16: =IF(AN9=YEAR(Input!$H$12),1,IF(AND(Расчеты!AN9>YEAR(Input!$H$12),Расчеты!AN9<=YEAR(Input!$H$14)),Расчеты!AM16+1,0)) -> 0
C17: Флаг дисконтирования | H17: х | L17: =IF(OR(L9<YEAR(Input!$H$10),L9>YEAR(Input!$H$14)),0,1) -> 0 | M17: =IF(OR(M9<YEAR(Input!$H$10),M9>YEAR(Input!$H$14)),0,1) -> 1 | N17: =IF(OR(N9<YEAR(Input!$H$10),N9>YEAR(Input!$H$14)),0,1) -> 1 | O17: =IF(OR(O9<YEAR(Input!$H$10),O9>YEAR(Input!$H$14)),0,1) -> 1 | P17: =IF(OR(P9<YEAR(Input!$H$10),P9>YEAR(Input!$H$14)),0,1) -> 1 | Q17: =IF(OR(Q9<YEAR(Input!$H$10),Q9>YEAR(Input!$H$14)),0,1) -> 1 | R17: =IF(OR(R9<YEAR(Input!$H$10),R9>YEAR(Input!$H$14)),0,1) -> 1 | S17: =IF(OR(S9<YEAR(Input!$H$10),S9>YEAR(Input!$H$14)),0,1) -> 1 | ... AN17: =IF(OR(AN9<YEAR(Input!$H$10),AN9>YEAR(Input!$H$14)),0,1) -> 0
C19: ФЛАГИ ПРОВЕДЕНИЯ РЕМОНТОВ
C21: Флаг проведения текущего ремонта оборудования | H21: х | L21: =IFERROR(IF(AND((INDEX($L$119:$AC$119,MATCH(L$423,$L$118:$AC$118,1)))="ТР",K$423<INDEX($L$118:$AC$118,MATCH(L$423,$L$118:$AC$118,1))),1,0),0) -> 0 | M21: =IFERROR(IF(AND((INDEX($L$119:$AC$119,MATCH(M$423,$L$118:$AC$118,1)))="ТР",L$423<INDEX($L$118:$AC$118,MATCH(M$423,$L$118:$AC$118,1))),1,0),0) -> 0 | N21: =IFERROR(IF(AND((INDEX($L$119:$AC$119,MATCH(N$423,$L$118:$AC$118,1)))="ТР",M$423<INDEX($L$118:$AC$118,MATCH(N$423,$L$118:$AC$118,1))),1,0),0) -> 0 | O21: =IFERROR(IF(AND((INDEX($L$119:$AC$119,MATCH(O$423,$L$118:$AC$118,1)))="ТР",N$423<INDEX($L$118:$AC$118,MATCH(O$423,$L$118:$AC$118,1))),1,0),0) -> 1 | P21: =IFERROR(IF(AND((INDEX($L$119:$AC$119,MATCH(P$423,$L$118:$AC$118,1)))="ТР",O$423<INDEX($L$118:$AC$118,MATCH(P$423,$L$118:$AC$118,1))),1,0),0) -> 1 | Q21: =IFERROR(IF(AND((INDEX($L$119:$AC$119,MATCH(Q$423,$L$118:$AC$118,1)))="ТР",P$423<INDEX($L$118:$AC$118,MATCH(Q$423,$L$118:$AC$118,1))),1,0),0) -> 1 | R21: =IFERROR(IF(AND((INDEX($L$119:$AC$119,MATCH(R$423,$L$118:$AC$118,1)))="ТР",Q$423<INDEX($L$118:$AC$118,MATCH(R$423,$L$118:$AC$118,1))),1,0),0) -> 0 | S21: =IFERROR(IF(AND((INDEX($L$119:$AC$119,MATCH(S$423,$L$118:$AC$118,1)))="ТР",R$423<INDEX($L$118:$AC$118,MATCH(S$423,$L$118:$AC$118,1))),1,0),0) -> 1 | ... AN21: =IFERROR(IF(AND((INDEX($L$119:$AC$119,MATCH(AN$423,$L$118:$AC$118,1)))="ТР",AM$423<INDEX($L$118:$AC$118,MATCH(AN$423,$L$118:$AC$118,1))),1,0),0) -> 0
C22: Флаг проведения среднего ремонта оборудования | H22: х | L22: =IFERROR(IF(AND((INDEX($L$119:$AC$119,MATCH(L$423,$L$118:$AC$118,1)))="СР",K$423<INDEX($L$118:$AC$118,MATCH(L$423,$L$118:$AC$118,1))),1,0),0) -> 0 | M22: =IFERROR(IF(AND((INDEX($L$119:$AC$119,MATCH(M$423,$L$118:$AC$118,1)))="СР",L$423<INDEX($L$118:$AC$118,MATCH(M$423,$L$118:$AC$118,1))),1,0),0) -> 0 | N22: =IFERROR(IF(AND((INDEX($L$119:$AC$119,MATCH(N$423,$L$118:$AC$118,1)))="СР",M$423<INDEX($L$118:$AC$118,MATCH(N$423,$L$118:$AC$118,1))),1,0),0) -> 0 | O22: =IFERROR(IF(AND((INDEX($L$119:$AC$119,MATCH(O$423,$L$118:$AC$118,1)))="СР",N$423<INDEX($L$118:$AC$118,MATCH(O$423,$L$118:$AC$118,1))),1,0),0) -> 0 | P22: =IFERROR(IF(AND((INDEX($L$119:$AC$119,MATCH(P$423,$L$118:$AC$118,1)))="СР",O$423<INDEX($L$118:$AC$118,MATCH(P$423,$L$118:$AC$118,1))),1,0),0) -> 0 | Q22: =IFERROR(IF(AND((INDEX($L$119:$AC$119,MATCH(Q$423,$L$118:$AC$118,1)))="СР",P$423<INDEX($L$118:$AC$118,MATCH(Q$423,$L$118:$AC$118,1))),1,0),0) -> 0 | R22: =IFERROR(IF(AND((INDEX($L$119:$AC$119,MATCH(R$423,$L$118:$AC$118,1)))="СР",Q$423<INDEX($L$118:$AC$118,MATCH(R$423,$L$118:$AC$118,1))),1,0),0) -> 1 | S22: =IFERROR(IF(AND((INDEX($L$119:$AC$119,MATCH(S$423,$L$118:$AC$118,1)))="СР",R$423<INDEX($L$118:$AC$118,MATCH(S$423,$L$118:$AC$118,1))),1,0),0) -> 0 | ... AN22: =IFERROR(IF(AND((INDEX($L$119:$AC$119,MATCH(AN$423,$L$118:$AC$118,1)))="СР",AM$423<INDEX($L$118:$AC$118,MATCH(AN$423,$L$118:$AC$118,1))),1,0),0) -> 0
C23: Флаг проведения капитального ремонта оборудования | H23: х | L23: =IFERROR(IF(AND((INDEX($L$119:$AC$119,MATCH(L$423,$L$118:$AC$118,1)))="КР",K$423<INDEX($L$118:$AC$118,MATCH(L$423,$L$118:$AC$118,1))),1,0),0) -> 0 | M23: =IFERROR(IF(AND((INDEX($L$119:$AC$119,MATCH(M$423,$L$118:$AC$118,1)))="КР",L$423<INDEX($L$118:$AC$118,MATCH(M$423,$L$118:$AC$118,1))),1,0),0) -> 0 | N23: =IFERROR(IF(AND((INDEX($L$119:$AC$119,MATCH(N$423,$L$118:$AC$118,1)))="КР",M$423<INDEX($L$118:$AC$118,MATCH(N$423,$L$118:$AC$118,1))),1,0),0) -> 0 | O23: =IFERROR(IF(AND((INDEX($L$119:$AC$119,MATCH(O$423,$L$118:$AC$118,1)))="КР",N$423<INDEX($L$118:$AC$118,MATCH(O$423,$L$118:$AC$118,1))),1,0),0) -> 0 | P23: =IFERROR(IF(AND((INDEX($L$119:$AC$119,MATCH(P$423,$L$118:$AC$118,1)))="КР",O$423<INDEX($L$118:$AC$118,MATCH(P$423,$L$118:$AC$118,1))),1,0),0) -> 0 | Q23: =IFERROR(IF(AND((INDEX($L$119:$AC$119,MATCH(Q$423,$L$118:$AC$118,1)))="КР",P$423<INDEX($L$118:$AC$118,MATCH(Q$423,$L$118:$AC$118,1))),1,0),0) -> 0 | R23: =IFERROR(IF(AND((INDEX($L$119:$AC$119,MATCH(R$423,$L$118:$AC$118,1)))="КР",Q$423<INDEX($L$118:$AC$118,MATCH(R$423,$L$118:$AC$118,1))),1,0),0) -> 0 | S23: =IFERROR(IF(AND((INDEX($L$119:$AC$119,MATCH(S$423,$L$118:$AC$118,1)))="КР",R$423<INDEX($L$118:$AC$118,MATCH(S$423,$L$118:$AC$118,1))),1,0),0) -> 0 | ... AN23: =IFERROR(IF(AND((INDEX($L$119:$AC$119,MATCH(AN$423,$L$118:$AC$118,1)))="КР",AM$423<INDEX($L$118:$AC$118,MATCH(AN$423,$L$118:$AC$118,1))),1,0),0) -> 0
C24: Флаг проведения текущего ремонта транспорта | H24: х | L24: =IFERROR(IF(AND((INDEX($L$129:$AC$129,MATCH(L$131,$L$128:$AC$128,1)))="ТР",K$131<INDEX($L$128:$AC$128,MATCH(L$131,$L$128:$AC$128,1))),1,0),0) -> 0 | M24: =IFERROR(IF(AND((INDEX($L$129:$AC$129,MATCH(M$131,$L$128:$AC$128,1)))="ТР",L$131<INDEX($L$128:$AC$128,MATCH(M$131,$L$128:$AC$128,1))),1,0),0) -> 0 | N24: =IFERROR(IF(AND((INDEX($L$129:$AC$129,MATCH(N$131,$L$128:$AC$128,1)))="ТР",M$131<INDEX($L$128:$AC$128,MATCH(N$131,$L$128:$AC$128,1))),1,0),0) -> 0 | O24: =IFERROR(IF(AND((INDEX($L$129:$AC$129,MATCH(O$131,$L$128:$AC$128,1)))="ТР",N$131<INDEX($L$128:$AC$128,MATCH(O$131,$L$128:$AC$128,1))),1,0),0) -> 1 | P24: =IFERROR(IF(AND((INDEX($L$129:$AC$129,MATCH(P$131,$L$128:$AC$128,1)))="ТР",O$131<INDEX($L$128:$AC$128,MATCH(P$131,$L$128:$AC$128,1))),1,0),0) -> 1 | Q24: =IFERROR(IF(AND((INDEX($L$129:$AC$129,MATCH(Q$131,$L$128:$AC$128,1)))="ТР",P$131<INDEX($L$128:$AC$128,MATCH(Q$131,$L$128:$AC$128,1))),1,0),0) -> 1 | R24: =IFERROR(IF(AND((INDEX($L$129:$AC$129,MATCH(R$131,$L$128:$AC$128,1)))="ТР",Q$131<INDEX($L$128:$AC$128,MATCH(R$131,$L$128:$AC$128,1))),1,0),0) -> 1 | S24: =IFERROR(IF(AND((INDEX($L$129:$AC$129,MATCH(S$131,$L$128:$AC$128,1)))="ТР",R$131<INDEX($L$128:$AC$128,MATCH(S$131,$L$128:$AC$128,1))),1,0),0) -> 1 | ... AN24: =IFERROR(IF(AND((INDEX($L$129:$AC$129,MATCH(AN$131,$L$128:$AC$128,1)))="ТР",AM$131<INDEX($L$128:$AC$128,MATCH(AN$131,$L$128:$AC$128,1))),1,0),0) -> 0
C25: Флаг проведения среднего ремонта транспорта | H25: х | L25: =IFERROR(IF(AND((INDEX($L$129:$AC$129,MATCH(L$131,$L$128:$AC$128,1)))="СР",K$131<INDEX($L$128:$AC$128,MATCH(L$131,$L$128:$AC$128,1))),1,0),0) -> 0 | M25: =IFERROR(IF(AND((INDEX($L$129:$AC$129,MATCH(M$131,$L$128:$AC$128,1)))="СР",L$131<INDEX($L$128:$AC$128,MATCH(M$131,$L$128:$AC$128,1))),1,0),0) -> 0 | N25: =IFERROR(IF(AND((INDEX($L$129:$AC$129,MATCH(N$131,$L$128:$AC$128,1)))="СР",M$131<INDEX($L$128:$AC$128,MATCH(N$131,$L$128:$AC$128,1))),1,0),0) -> 0 | O25: =IFERROR(IF(AND((INDEX($L$129:$AC$129,MATCH(O$131,$L$128:$AC$128,1)))="СР",N$131<INDEX($L$128:$AC$128,MATCH(O$131,$L$128:$AC$128,1))),1,0),0) -> 0 | P25: =IFERROR(IF(AND((INDEX($L$129:$AC$129,MATCH(P$131,$L$128:$AC$128,1)))="СР",O$131<INDEX($L$128:$AC$128,MATCH(P$131,$L$128:$AC$128,1))),1,0),0) -> 0 | Q25: =IFERROR(IF(AND((INDEX($L$129:$AC$129,MATCH(Q$131,$L$128:$AC$128,1)))="СР",P$131<INDEX($L$128:$AC$128,MATCH(Q$131,$L$128:$AC$128,1))),1,0),0) -> 0 | R25: =IFERROR(IF(AND((INDEX($L$129:$AC$129,MATCH(R$131,$L$128:$AC$128,1)))="СР",Q$131<INDEX($L$128:$AC$128,MATCH(R$131,$L$128:$AC$128,1))),1,0),0) -> 0 | S25: =IFERROR(IF(AND((INDEX($L$129:$AC$129,MATCH(S$131,$L$128:$AC$128,1)))="СР",R$131<INDEX($L$128:$AC$128,MATCH(S$131,$L$128:$AC$128,1))),1,0),0) -> 0 | ... AN25: =IFERROR(IF(AND((INDEX($L$129:$AC$129,MATCH(AN$131,$L$128:$AC$128,1)))="СР",AM$131<INDEX($L$128:$AC$128,MATCH(AN$131,$L$128:$AC$128,1))),1,0),0) -> 0
C26: Флаг проведения капитального ремонта транспорта | H26: х | L26: =IFERROR(IF(AND((INDEX($L$129:$AC$129,MATCH(L$131,$L$128:$AC$128,1)))="КР",K$131<INDEX($L$128:$AC$128,MATCH(L$131,$L$128:$AC$128,1))),1,0),0) -> 0 | M26: =IFERROR(IF(AND((INDEX($L$129:$AC$129,MATCH(M$131,$L$128:$AC$128,1)))="КР",L$131<INDEX($L$128:$AC$128,MATCH(M$131,$L$128:$AC$128,1))),1,0),0) -> 0 | N26: =IFERROR(IF(AND((INDEX($L$129:$AC$129,MATCH(N$131,$L$128:$AC$128,1)))="КР",M$131<INDEX($L$128:$AC$128,MATCH(N$131,$L$128:$AC$128,1))),1,0),0) -> 0 | O26: =IFERROR(IF(AND((INDEX($L$129:$AC$129,MATCH(O$131,$L$128:$AC$128,1)))="КР",N$131<INDEX($L$128:$AC$128,MATCH(O$131,$L$128:$AC$128,1))),1,0),0) -> 0 | P26: =IFERROR(IF(AND((INDEX($L$129:$AC$129,MATCH(P$131,$L$128:$AC$128,1)))="КР",O$131<INDEX($L$128:$AC$128,MATCH(P$131,$L$128:$AC$128,1))),1,0),0) -> 0 | Q26: =IFERROR(IF(AND((INDEX($L$129:$AC$129,MATCH(Q$131,$L$128:$AC$128,1)))="КР",P$131<INDEX($L$128:$AC$128,MATCH(Q$131,$L$128:$AC$128,1))),1,0),0) -> 0 | R26: =IFERROR(IF(AND((INDEX($L$129:$AC$129,MATCH(R$131,$L$128:$AC$128,1)))="КР",Q$131<INDEX($L$128:$AC$128,MATCH(R$131,$L$128:$AC$128,1))),1,0),0) -> 0 | S26: =IFERROR(IF(AND((INDEX($L$129:$AC$129,MATCH(S$131,$L$128:$AC$128,1)))="КР",R$131<INDEX($L$128:$AC$128,MATCH(S$131,$L$128:$AC$128,1))),1,0),0) -> 0 | ... AN26: =IFERROR(IF(AND((INDEX($L$129:$AC$129,MATCH(AN$131,$L$128:$AC$128,1)))="КР",AM$131<INDEX($L$128:$AC$128,MATCH(AN$131,$L$128:$AC$128,1))),1,0),0) -> 0
C27: Флаг проведения текущего ремонта зданий и сооружений | H27: х | L27: =IFERROR(IF((INDEX($L$109:$AC$109,MATCH(L$16,$L$108:$AC$108,0)))="ТР",1,0),0) -> 0 | M27: =IFERROR(IF((INDEX($L$109:$AC$109,MATCH(M$16,$L$108:$AC$108,0)))="ТР",1,0),0) -> 0 | N27: =IFERROR(IF((INDEX($L$109:$AC$109,MATCH(N$16,$L$108:$AC$108,0)))="ТР",1,0),0) -> 1 | O27: =IFERROR(IF((INDEX($L$109:$AC$109,MATCH(O$16,$L$108:$AC$108,0)))="ТР",1,0),0) -> 1 | P27: =IFERROR(IF((INDEX($L$109:$AC$109,MATCH(P$16,$L$108:$AC$108,0)))="ТР",1,0),0) -> 1 | Q27: =IFERROR(IF((INDEX($L$109:$AC$109,MATCH(Q$16,$L$108:$AC$108,0)))="ТР",1,0),0) -> 1 | R27: =IFERROR(IF((INDEX($L$109:$AC$109,MATCH(R$16,$L$108:$AC$108,0)))="ТР",1,0),0) -> 0 | S27: =IFERROR(IF((INDEX($L$109:$AC$109,MATCH(S$16,$L$108:$AC$108,0)))="ТР",1,0),0) -> 0 | ... AN27: =IFERROR(IF((INDEX($L$109:$AC$109,MATCH(AN$16,$L$108:$AC$108,0)))="ТР",1,0),0) -> 0
C28: Флаг проведения среднего ремонта зданий и сооружений | H28: х | L28: =IFERROR(IF((INDEX($L$109:$AC$109,MATCH(L$16,$L$108:$AC$108,0)))="СР",1,0),0) -> 0 | M28: =IFERROR(IF((INDEX($L$109:$AC$109,MATCH(M$16,$L$108:$AC$108,0)))="СР",1,0),0) -> 0 | N28: =IFERROR(IF((INDEX($L$109:$AC$109,MATCH(N$16,$L$108:$AC$108,0)))="СР",1,0),0) -> 0 | O28: =IFERROR(IF((INDEX($L$109:$AC$109,MATCH(O$16,$L$108:$AC$108,0)))="СР",1,0),0) -> 0 | P28: =IFERROR(IF((INDEX($L$109:$AC$109,MATCH(P$16,$L$108:$AC$108,0)))="СР",1,0),0) -> 0 | Q28: =IFERROR(IF((INDEX($L$109:$AC$109,MATCH(Q$16,$L$108:$AC$108,0)))="СР",1,0),0) -> 0 | R28: =IFERROR(IF((INDEX($L$109:$AC$109,MATCH(R$16,$L$108:$AC$108,0)))="СР",1,0),0) -> 1 | S28: =IFERROR(IF((INDEX($L$109:$AC$109,MATCH(S$16,$L$108:$AC$108,0)))="СР",1,0),0) -> 0 | ... AN28: =IFERROR(IF((INDEX($L$109:$AC$109,MATCH(AN$16,$L$108:$AC$108,0)))="СР",1,0),0) -> 0
C29: Флаг проведения капитального ремонта зданий и сооружений | H29: х | L29: =IFERROR(IF((INDEX($L$109:$AC$109,MATCH(L$16,$L$108:$AC$108,0)))="КР",1,0),0) -> 0 | M29: =IFERROR(IF((INDEX($L$109:$AC$109,MATCH(M$16,$L$108:$AC$108,0)))="КР",1,0),0) -> 0 | N29: =IFERROR(IF((INDEX($L$109:$AC$109,MATCH(N$16,$L$108:$AC$108,0)))="КР",1,0),0) -> 0 | O29: =IFERROR(IF((INDEX($L$109:$AC$109,MATCH(O$16,$L$108:$AC$108,0)))="КР",1,0),0) -> 0 | P29: =IFERROR(IF((INDEX($L$109:$AC$109,MATCH(P$16,$L$108:$AC$108,0)))="КР",1,0),0) -> 0 | Q29: =IFERROR(IF((INDEX($L$109:$AC$109,MATCH(Q$16,$L$108:$AC$108,0)))="КР",1,0),0) -> 0 | R29: =IFERROR(IF((INDEX($L$109:$AC$109,MATCH(R$16,$L$108:$AC$108,0)))="КР",1,0),0) -> 0 | S29: =IFERROR(IF((INDEX($L$109:$AC$109,MATCH(S$16,$L$108:$AC$108,0)))="КР",1,0),0) -> 1 | ... AN29: =IFERROR(IF((INDEX($L$109:$AC$109,MATCH(AN$16,$L$108:$AC$108,0)))="КР",1,0),0) -> 0
C31: НАЛОГОВОЕ ОКРУЖЕНИЕ ПРОЕКТА
C33: =Input!B31 -> Доля прибыли к зачету против убытков | H33: % | L33: =Input!L31 -> 0.5 | M33: =Input!M31 -> 0.5 | N33: =Input!N31 -> 0.5 | O33: =Input!O31 -> 0.5 | P33: =Input!P31 -> 0.5 | Q33: =Input!Q31 -> 0.5 | R33: =Input!R31 -> 0.5 | S33: =Input!S31 -> 0.5 | ... AN33: =Input!AN31 -> 0
C34: =Input!B32 -> НДС | H34: % | L34: =Input!L32 -> 0.2 | M34: =Input!M32 -> 0.2 | N34: =Input!N32 -> 0.2 | O34: =Input!O32 -> 0.2 | P34: =Input!P32 -> 0.2 | Q34: =Input!Q32 -> 0.2 | R34: =Input!R32 -> 0.2 | S34: =Input!S32 -> 0.2 | ... AN34: =Input!AN32 -> 0
C35: =Input!B33 -> Ставка налога на прибыль | H35: % | L35: =Input!L33 -> 0.2 | M35: =Input!M33 -> 0.25 | N35: =Input!N33 -> 0.25 | O35: =Input!O33 -> 0.25 | P35: =Input!P33 -> 0.25 | Q35: =Input!Q33 -> 0.25 | R35: =Input!R33 -> 0.25 | S35: =Input!S33 -> 0.25 | ... AN35: =Input!AN33 -> 0
C36: =Input!B34 -> Ставка налога на имущество | H36: % | L36: =Input!L34 -> 0.022 | M36: =Input!M34 -> 0.022 | N36: =Input!N34 -> 0.022 | O36: =Input!O34 -> 0.022 | P36: =Input!P34 -> 0.022 | Q36: =Input!Q34 -> 0.022 | R36: =Input!R34 -> 0.022 | S36: =Input!S34 -> 0.022 | ... AN36: =Input!AN34 -> 0
C37: =Input!B35 -> Ставка налога на землю | H37: % | L37: =Input!L35 -> 0.015 | M37: =Input!M35 -> 0.015 | N37: =Input!N35 -> 0.015 | O37: =Input!O35 -> 0.015 | P37: =Input!P35 -> 0.015 | Q37: =Input!Q35 -> 0.015 | R37: =Input!R35 -> 0.015 | S37: =Input!S35 -> 0.015 | ... AN37: =Input!AN35 -> 0
C38: =Input!B36 -> Ставка транспортного налога | H38: руб/л.с. | L38: =Input!L36 -> 2.5 | M38: =Input!M36 -> 2.5 | N38: =Input!N36 -> 2.5 | O38: =Input!O36 -> 2.5 | P38: =Input!P36 -> 2.5 | Q38: =Input!Q36 -> 2.5 | R38: =Input!R36 -> 2.5 | S38: =Input!S36 -> 2.5 | ... AN38: =Input!AN36 -> 0
C39: =Input!B37 -> Социальные отчисления (ПФР, ФСС, ФОМС) | H39: % | L39: =Input!L37 -> 0.302 | M39: =Input!M37 -> 0.302 | N39: =Input!N37 -> 0.302 | O39: =Input!O37 -> 0.302 | P39: =Input!P37 -> 0.302 | Q39: =Input!Q37 -> 0.302 | R39: =Input!R37 -> 0.302 | S39: =Input!S37 -> 0.302 | ... AN39: =Input!AN37 -> 0
C40: =Input!B38 -> Социальные отчисления от несчастных случаев и проф. заболеваний (рабочие) | H40: % | L40: =Input!L38 -> 0.08 | M40: =Input!M38 -> 0.08 | N40: =Input!N38 -> 0.08 | O40: =Input!O38 -> 0.08 | P40: =Input!P38 -> 0.08 | Q40: =Input!Q38 -> 0.08 | R40: =Input!R38 -> 0.08 | S40: =Input!S38 -> 0.08 | ... AN40: =Input!AN38 -> 0
C41: =Input!B39 -> Социальные отчисления от несчастных случаев и проф. заболеваний (служащие) | H41: % | L41: =Input!L39 -> 0.05 | M41: =Input!M39 -> 0.05 | N41: =Input!N39 -> 0.05 | O41: =Input!O39 -> 0.05 | P41: =Input!P39 -> 0.05 | Q41: =Input!Q39 -> 0.05 | R41: =Input!R39 -> 0.05 | S41: =Input!S39 -> 0.05 | ... AN41: =Input!AN39 -> 0
C43: МАКРОЭКОНОМИЧЕСКИЕ ПАРАМЕТРЫ ПРОЕКТА
C45: =Input!B21 -> Обменный курс рубля к доллару | H45: RUB/USD | L45: =Input!L21 -> 59 | M45: =Input!M21 -> 60 | N45: =Input!N21 -> 61 | O45: =Input!O21 -> 62 | P45: =Input!P21 -> 63 | Q45: =Input!Q21 -> 59 | R45: =Input!R21 -> 59 | S45: =Input!S21 -> 59 | ... AN45: =Input!AN21 -> 0
C46: Ключевая ставка ЦБ РФ | H46: % | L46: =Input!L27 -> 0.21 | M46: =Input!M27 -> 0.2 | N46: =Input!N27 -> 0.15 | O46: =Input!O27 -> 0.11 | P46: =Input!P27 -> 0.1 | Q46: =Input!Q27 -> 0.08 | R46: =Input!R27 -> 0.07 | S46: =Input!S27 -> 0.07 | ... AN46: =Input!AN27 -> 0
C48: Цепные индексы инфляции
C50: =Input!B22 -> CPI, (RUB) | H50: х | L50: =Input!L22 -> 1.04 | M50: =Input!M22 -> 1.04 | N50: =Input!N22 -> 1.04 | O50: =Input!O22 -> 1.04 | P50: =Input!P22 -> 1.04 | Q50: =Input!Q22 -> 1.04 | R50: =Input!R22 -> 1.04 | S50: =Input!S22 -> 1.04 | ... AN50: =Input!AN22 -> 0
...

Sheet PL_BS_CF
A1: =Title!$C$16 -> Строительство производства сухих строительных смесей
A2: =Title!$C$15 -> Финансово-экономическая модель | L2: {=Input!L2:L4} -> 45292 | M2: {=Input!M2:M4} -> 45658 | N2: {=Input!N2:N4} -> 46023 | O2: {=Input!O2:O4} -> 46388 | P2: {=Input!P2:P4} -> 46753 | Q2: {=Input!Q2:Q4} -> 47119 | R2: {=Input!R2:R4} -> 47484 | S2: {=Input!S2:S4} -> 47849 | ... AN2: {=Input!AN2:AN4}
A3: Прогноз 3-х форм финансовой отчетности | L3: 45657 | M3: 46022 | N3: 46387 | O3: 46752 | P3: 47118 | Q3: 47483 | R3: 47848 | S3: 48213 | T3: 48579 | U3: 48944 | V3: 49309 | W3: 49674 | X3: 50040 | Y3: 50405 | Z3: 50770 | AA3: 51135 | AB3: 51501 | AC3: 51866
L4: Факт | M4: Прогноз | N4: Прогноз | O4: Прогноз | P4: Прогноз | Q4: Прогноз | R4: Прогноз | S4: Прогноз | T4: Прогноз | U4: Прогноз | V4: Прогноз | W4: Прогноз | X4: Прогноз | Y4: Прогноз | Z4: Прогноз | AA4: Прогноз | AB4: Прогноз | AC4: Прогноз
G5: Ед. измерения | H5: Значение/База | K5: Сумма
B7: PL
B9: Выручка | G9: млн. руб. | K9: =SUM(L9:AN9) -> 16563.793 | L9: =Расчеты!L444 -> 0 | M9: =Расчеты!M444 -> 0 | N9: =Расчеты!N444 -> 684.26283 | O9: =Расчеты!O444 -> 853.96001 | P9: =Расчеты!P444 -> 890.55161 | Q9: =Расчеты!Q444 -> 923.64315 | R9: =Расчеты!R444 -> 960.58888 | S9: =Расчеты!S444 -> 999.01243 | ... AN9: =Расчеты!AN444 -> 0
B11: Себестоимость | G11: млн. руб. | K11: =SUM(L11:AN11) -> 12524.967 | L11: =Расчеты!L603 -> 0 | M11: =Расчеты!M603 -> 0 | N11: =Расчеты!N603 -> 558.15789 | O11: =Расчеты!O603 -> 696.60167 | P11: =Расчеты!P603 -> 726.47228 | Q11: =Расчеты!Q603 -> 753.48961 | R11: =Расчеты!R603 -> 783.65307 | S11: =Расчеты!S603 -> 815.02425 | ... AN11: =Расчеты!AN603 -> 0
B13: Маржинальная прибыль | G13: млн. руб. | K13: =SUM(L13:AN13) -> 4038.826 | L13: =L9-L11 -> 0 | M13: =M9-M11 -> 0 | N13: =N9-N11 -> 126.10494 | O13: =O9-O11 -> 157.35834 | P13: =P9-P11 -> 164.07933 | Q13: =Q9-Q11 -> 170.15353 | R13: =R9-R11 -> 176.93581 | S13: =S9-S11 -> 183.98818 | ... AN13: =AN9-AN11 -> 0
B14: % рентабельность по маржинальной прибыли | L14: =IFERROR(L13/L9,0) -> 0 | M14: =IFERROR(M13/M9,0) -> 0 | N14: =IFERROR(N13/N9,0) -> 0.18429313 | O14: =IFERROR(O13/O9,0) -> 0.18426898 | P14: =IFERROR(P13/P9,0) -> 0.1842446 | Q14: =IFERROR(Q13/Q9,0) -> 0.18421999 | R14: =IFERROR(R13/R9,0) -> 0.18419514 | S14: =IFERROR(S13/S9,0) -> 0.18417006 | ... AN14: =IFERROR(AN13/AN9,0) -> 0
B16: Общепроизводственные и административные расходы | G16: млн. руб. | K16: =SUM(L16:AN16) -> 1658.7136 | L16: =Расчеты!L619+Расчеты!L627 -> 0 | M16: =Расчеты!M619+Расчеты!M627 -> 0 | N16: =Расчеты!N619+Расчеты!N627 -> 68.534347 | O16: =Расчеты!O619+Расчеты!O627 -> 85.536929 | P16: =Расчеты!P619+Расчеты!P627 -> 88.964773 | Q16: =Расчеты!Q619+Расчеты!Q627 -> 92.530049 | R16: =Расчеты!R619+Расчеты!R627 -> 96.238271 | S16: =Расчеты!S619+Расчеты!S627 -> 100.09517 | ... AN16: =Расчеты!AN619+Расчеты!AN627 -> 0
B18: Расходы на текущий ремонт | G18: млн. руб. | K18: =SUM(L18:AN18) -> 247.42017 | L18: =Расчеты!L632 -> 0 | M18: =Расчеты!M632 -> 0 | N18: =Расчеты!N632 -> 1.29792 | O18: =Расчеты!O632 -> 13.723341 | P18: =Расчеты!P632 -> 14.272274 | Q18: =Расчеты!Q632 -> 14.843165 | R18: =Расчеты!R632 -> 25.685976 | S18: =Расчеты!S632 -> 14.47525 | ... AN18: =Расчеты!AN632 -> 0
B20: Налоги (кроме налога на прибыль) | G20: млн. руб. | K20: =SUM(L20:AN20) -> 9.4096749 | L20: =Расчеты!L807+Расчеты!L817+Расчеты!L825 -> 0 | M20: =Расчеты!M807+Расчеты!M817+Расчеты!M825 -> 0 | N20: =Расчеты!N807+Расчеты!N817+Расчеты!N825 -> 2.1840576 | O20: =Расчеты!O807+Расчеты!O817+Расчеты!O825 -> 2.0071786 | P20: =Расчеты!P807+Расчеты!P817+Расчеты!P825 -> 1.5528347 | Q20: =Расчеты!Q807+Расчеты!Q817+Расчеты!Q825 -> 1.0984908 | R20: =Расчеты!R807+Расчеты!R817+Расчеты!R825 -> 0.64414687 | S20: =Расчеты!S807+Расчеты!S817+Расчеты!S825 -> 0.37747952 | ... AN20: =Расчеты!AN807+Расчеты!AN817+Расчеты!AN825 -> 0
B22: EBITDА | G22: млн. руб. | K22: =SUM(L22:AN22) -> 2123.2826 | L22: =L13-L16-L18-L20 -> 0 | M22: =M13-M16-M18-M20 -> 0 | N22: =N13-N16-N18-N20 -> 54.088612 | O22: =O13-O16-O18-O20 -> 56.090894 | P22: =P13-P16-P18-P20 -> 59.289448 | Q22: =Q13-Q16-Q18-Q20 -> 61.681829 | R22: =R13-R16-R18-R20 -> 54.367413 | S22: =S13-S16-S18-S20 -> 69.040275 | ... AN22: =AN13-AN16-AN18-AN20 -> 0
B23: % рентабельность по EBITDA | L23: =IFERROR(L22/L9,0) -> 0 | M23: =IFERROR(M22/M9,0) -> 0 | N23: =IFERROR(N22/N9,0) -> 0.079046544 | O23: =IFERROR(O22/O9,0) -> 0.065683279 | P23: =IFERROR(P22/P9,0) -> 0.066576094 | Q23: =IFERROR(Q22/Q9,0) -> 0.066781017 | R23: =IFERROR(R22/R9,0) -> 0.056598004 | S23: =IFERROR(S22/S9,0) -> 0.069108525 | ... AN23: =IFERROR(AN22/AN9,0) -> 0
B25: Амортизация | G25: млн. руб. | K25: =SUM(L25:AN25) -> 354.82757 | L25: =Расчеты!L152 -> 0 | M25: =Расчеты!M152 -> 0 | N25: =Расчеты!N152 -> 36.617665 | O25: =Расчеты!O152 -> 43.941198 | P25: =Расчеты!P152 -> 43.941198 | Q25: =Расчеты!Q152 -> 43.941198 | R25: =Расчеты!R152 -> 43.941198 | S25: =Расчеты!S152 -> 14.292353 | ... AN25: =Расчеты!AN152 -> 0
B27: EBIT | G27: млн. руб. | K27: =SUM(L27:AN27) -> 1768.455 | L27: =L22-L25 -> 0 | M27: =M22-M25 -> 0 | N27: =N22-N25 -> 17.470947 | O27: =O22-O25 -> 12.149696 | P27: =P22-P25 -> 15.34825 | Q27: =Q22-Q25 -> 17.740631 | R27: =R22-R25 -> 10.426215 | S27: =S22-S25 -> 54.747923 | ... AN27: =AN22-AN25 -> 0
B28: % рентабельность по EBIT | L28: =IFERROR(L27/L9,0) -> 0 | M28: =IFERROR(M27/M9,0) -> 0 | N28: =IFERROR(N27/N9,0) -> 0.02553251 | O28: =IFERROR(O27/O9,0) -> 0.014227476 | P28: =IFERROR(P27/P9,0) -> 0.017234543 | Q28: =IFERROR(Q27/Q9,0) -> 0.019207235 | R28: =IFERROR(R27/R9,0) -> 0.010853983 | S28: =IFERROR(S27/S9,0) -> 0.054802043 | ... AN28: =IFERROR(AN27/AN9,0) -> 0
B30: Процентные расходы | G30: млн. руб. | K30: =SUM(L30:AN30) -> 168.80782 | L30: =Расчеты!L741 -> 0 | M30: =Расчеты!M741 -> 0 | N30: =Расчеты!N741 -> 37.499942 | O30: =Расчеты!O741 -> 32.400404 | P30: =Расчеты!P741 -> 26.849149 | Q30: =Расчеты!Q741 -> 20.260063 | R30: =Расчеты!R741 -> 15.866096 | S30: =Расчеты!S741 -> 12.972875 | ... AN30: =Расчеты!AN741 -> 0
B32: EBT | G32: млн. руб. | K32: =SUM(L32:AN32) -> 1599.6472 | L32: =L27-L30 -> 0 | M32: =M27-M30 -> 0 | N32: =N27-N30 -> -20.028995 | O32: =O27-O30 -> -20.250708 | P32: =P27-P30 -> -11.500899 | Q32: =Q27-Q30 -> -2.5194321 | R32: =R27-R30 -> -5.4398812 | S32: =S27-S30 -> 41.775048 | ... AN32: =AN27-AN30 -> 0
B33: % рентабельность по EBT | L33: =IFERROR(L32/L9,0) -> 0 | M33: =IFERROR(M32/M9,0) -> 0 | N33: =IFERROR(N32/N9,0) -> -0.029270909 | O33: =IFERROR(O32/O9,0) -> -0.023713884 | P33: =IFERROR(P32/P9,0) -> -0.012914354 | Q33: =IFERROR(Q32/Q9,0) -> -0.0027277116 | R33: =IFERROR(R32/R9,0) -> -0.0056630691 | S33: =IFERROR(S32/S9,0) -> 0.041816344 | ... AN33: =IFERROR(AN32/AN9,0) -> 0
B35: Налог на прибыль | G35: млн. руб. | K35: =SUM(L35:AN35) -> 414.84678 | L35: =Расчеты!L843 -> 0 | M35: =Расчеты!M843 -> 0 | N35: =Расчеты!N843 -> 0 | O35: =Расчеты!O843 -> 0 | P35: =Расчеты!P843 -> 0 | Q35: =Расчеты!Q843 -> 0 | R35: =Расчеты!R843 -> 0 | S35: =Расчеты!S843 -> 10.443762 | ... AN35: =Расчеты!AN843 -> 0
B37: Чистая прибыль | K37: =SUM(L37:AN37) -> 1184.8004 | L37: =L32-L35 -> 0 | M37: =M32-M35 -> 0 | N37: =N32-N35 -> -20.028995 | O37: =O32-O35 -> -20.250708 | P37: =P32-P35 -> -11.500899 | Q37: =Q32-Q35 -> -2.5194321 | R37: =R32-R35 -> -5.4398812 | S37: =S32-S35 -> 31.331286 | ... AN37: =AN32-AN35 -> 0
B38: % рентабельность по чистой прибыли | G38: % | L38: =IFERROR(L37/L$9,0) -> 0 | M38: =IFERROR(M37/M$9,0) -> 0 | N38: =IFERROR(N37/N$9,0) -> -0.029270909 | O38: =IFERROR(O37/O$9,0) -> -0.023713884 | P38: =IFERROR(P37/P$9,0) -> -0.012914354 | Q38: =IFERROR(Q37/Q$9,0) -> -0.0027277116 | R38: =IFERROR(R37/R$9,0) -> -0.0056630691 | S38: =IFERROR(S37/S$9,0) -> 0.031362258 | ... AN38: =IFERROR(AN37/AN$9,0) -> 0
B40: Долг/EBITDA | G40: x | L40: =IFERROR((L63+L66)/L22,0) -> 0 | M40: =IFERROR((M63+M66)/M22,0) -> 0 | N40: =IFERROR((N63+N66)/N22,0) -> 3.6304516 | O40: =IFERROR((O63+O66)/O22,0) -> 3.0882074 | P40: =IFERROR((P63+P66)/P22,0) -> 2.5312184 | Q40: =IFERROR((Q63+Q66)/Q22,0) -> 2.0577984 | R40: =IFERROR((R63+R66)/R22,0) -> 1.9089192 | S40: =IFERROR((S63+S66)/S22,0) -> 1.1679737 | ... AN40: =IFERROR((AN63+AN66)/AN22,0) -> 0
B42: BS
B44: ВНЕОБОРОТНЫЕ АКТИВЫ | G44: млн. руб. | L44: =SUM(L45:L46) -> 0 | M44: =SUM(M45:M46) -> 176.06554 | N44: =SUM(N45:N46) -> 226.95625 | O44: =SUM(O45:O46) -> 183.01505 | P44: =SUM(P45:P46) -> 139.07385 | Q44: =SUM(Q45:Q46) -> 95.132656 | R44: =SUM(R45:R46) -> 51.191458 | S44: =SUM(S45:S46) -> 41.373273 | ... AN44: =SUM(AN45:AN46) -> 7.1054274e-14
C45: Основные средства | G45: млн. руб. | L45: =Расчеты!L154 -> 0 | M45: =Расчеты!M154 -> 0 | N45: =Расчеты!N154 -> 226.95625 | O45: =Расчеты!O154 -> 183.01505 | P45: =Расчеты!P154 -> 139.07385 | Q45: =Расчеты!Q154 -> 95.132656 | R45: =Расчеты!R154 -> 51.191458 | S45: =Расчеты!S154 -> 41.373273 | ... AN45: =Расчеты!AN154 -> 0
C46: Незавершенные капитальные вложения | G46: млн. руб. | L46: =Расчеты!L148 -> 0 | M46: =Расчеты!M148 -> 176.06554 | N46: =Расчеты!N148 -> 0 | O46: =Расчеты!O148 -> 0 | P46: =Расчеты!P148 -> 0 | Q46: =Расчеты!Q148 -> 0 | R46: =Расчеты!R148 -> 0 | S46: =Расчеты!S148 -> 1.7763568e-14 | ... AN46: =Расчеты!AN148 -> 7.1054274e-14
B48: ОБОРОТНЫЕ АКТИВЫ | L48: =SUM(L49:L54) -> 0 | M48: =SUM(M49:M54) -> 22.398481 | N48: =SUM(N49:N54) -> 138.87799 | O48: =SUM(O49:O54) -> 149.44107 | P48: =SUM(P49:P54) -> 161.56214 | Q48: =SUM(Q49:Q54) -> 182.85258 | R48: =SUM(R49:R54) -> 201.59629 | S48: =SUM(S49:S54) -> 227.1989 | ... AN48: =SUM(AN49:AN54) -> 1327.029
C49: Запасы | G49: млн. руб. | L49: =Расчеты!L923 -> 0 | M49: =Расчеты!M923 -> 0 | N49: =Расчеты!N923 -> 18.293906 | O49: =Расчеты!O923 -> 19.025662 | P49: =Расчеты!P923 -> 19.786689 | Q49: =Расчеты!Q923 -> 20.578156 | R49: =Расчеты!R923 -> 21.401283 | S49: =Расчеты!S923 -> 22.257334 | ... AN49: =Расчеты!AN923 -> 0
C50: Дебиторская задолженость | G50: млн. руб. | L50: =Расчеты!L922+Расчеты!L924 -> 0 | M50: =Расчеты!M922+Расчеты!M924 -> 5.5229132 | N50: =Расчеты!N922+Расчеты!N924 -> 67.488937 | O50: =Расчеты!O922+Расчеты!O924 -> 70.188494 | P50: =Расчеты!P922+Расчеты!P924 -> 72.996034 | Q50: =Расчеты!Q922+Расчеты!Q924 -> 75.915875 | R50: =Расчеты!R922+Расчеты!R924 -> 78.95251 | S50: =Расчеты!S922+Расчеты!S924 -> 82.110611 | ... AN50: =Расчеты!AN922+Расчеты!AN924 -> 0
C51: НДС на балансе | G51: млн. руб. | L51: =Расчеты!L894 -> 0 | M51: =Расчеты!M894 -> 0 | N51: =Расчеты!N894 -> 0 | O51: =Расчеты!O894 -> 0 | P51: =Расчеты!P894 -> 0 | Q51: =Расчеты!Q894 -> 0 | R51: =Расчеты!R894 -> 0 | S51: =Расчеты!S894 -> 0 | ... AN51: =Расчеты!AN894 -> 0
C52: Денежные средства | G52: млн. руб. | L52: =L96 -> 0 | M52: =M96 -> 16.875568 | N52: =N96 -> 53.095143 | O52: =O96 -> 60.226915 | P52: =P96 -> 68.779413 | Q52: =Q96 -> 85.946064 | R52: =R96 -> 100.78259 | S52: =S96 -> 122.83095 | ... AN52: =AN96 -> 1327.029
C53: Авансы выданные поставщикам за капитальные вложения | G53: млн. руб. | L53: =IF(Расчеты!L91<0,-Расчеты!L91,0) -> 0 | M53: =IF(Расчеты!M91<0,-Расчеты!M91,0) -> 0 | N53: =IF(Расчеты!N91<0,-Расчеты!N91,0) -> 0 | O53: =IF(Расчеты!O91<0,-Расчеты!O91,0) -> 0 | P53: =IF(Расчеты!P91<0,-Расчеты!P91,0) -> 0 | Q53: =IF(Расчеты!Q91<0,-Расчеты!Q91,0) -> 0 | R53: =IF(Расчеты!R91<0,-Расчеты!R91,0) -> 0 | S53: =IF(Расчеты!S91<0,-Расчеты!S91,0) -> 0 | ... AN53: =IF(Расчеты!AN91<0,-Расчеты!AN91,0) -> 0
C54: Отложенные налоговые активы | G54: млн. руб. | L54: =IF(Расчеты!L876>0,Расчеты!L876,0) -> 0 | M54: =IF(Расчеты!M876>0,Расчеты!M876,0) -> 0 | N54: =IF(Расчеты!N876>0,Расчеты!N876,0) -> 0 | O54: =IF(Расчеты!O876>0,Расчеты!O876,0) -> 0 | P54: =IF(Расчеты!P876>0,Расчеты!P876,0) -> 0 | Q54: =IF(Расчеты!Q876>0,Расчеты!Q876,0) -> 0.41248202 | R54: =IF(Расчеты!R876>0,Расчеты!R876,0) -> 0.4599079 | S54: =IF(Расчеты!S876>0,Расчеты!S876,0) -> 0 | ... AN54: =IF(Расчеты!AN876>0,Расчеты!AN876,0) -> 0
B56: ИТОГО АКТИВ | G56: млн. руб. | L56: =L44+L48 -> 0 | M56: =M44+M48 -> 198.46402 | N56: =N44+N48 -> 365.83424 | O56: =O44+O48 -> 332.45612 | P56: =P44+P48 -> 300.63599 | Q56: =Q44+Q48 -> 277.98523 | R56: =R44+R48 -> 252.78775 | S56: =S44+S48 -> 268.57217 | ... AN56: =AN44+AN48 -> 1327.029
B58: КАПИТАЛ И РЕЗЕРВЫ | G58: млн. руб. | L58: =L59+L60 -> 0 | M58: =M59+M60 -> 54.293919 | N58: =N59+N60 -> 107.26464 | O58: =O59+O60 -> 87.013933 | P58: =P59+P60 -> 75.513034 | Q58: =Q59+Q60 -> 72.993602 | R58: =R59+R60 -> 67.553721 | S58: =S59+S60 -> 98.885007 | ... AN58: =AN59+AN60 -> 1312.094
C59: Уставной капитал | G59: млн. руб. | L59: =K59+L89 -> 0 | M59: =L59+M89 -> 54.293919 | N59: =M59+N89 -> 127.29364 | O59: =N59+O89 -> 127.29364 | P59: =O59+P89 -> 127.29364 | Q59: =P59+Q89 -> 127.29364 | R59: =Q59+R89 -> 127.29364 | S59: =R59+S89 -> 127.29364 | ... AN59: =AM59+AN89 -> 127.29364
C60: Нераспределенная прибыль | G60: млн. руб. | L60: =L37+K60 -> 0 | M60: =M37+L60 -> 0 | N60: =N37+M60 -> -20.028995 | O60: =O37+N60 -> -40.279703 | P60: =P37+O60 -> -51.780602 | Q60: =Q37+P60 -> -54.300034 | R60: =R37+Q60 -> -59.739915 | S60: =S37+R60 -> -28.40863 | ... AN60: =AN37+AM60 -> 1184.8004
...

Sheet Тех.лист
C2: Индексация | E2: Ремонты | G2: Тип платежа
C3: Без индексации | E3: ТР | G3: Аннуитетный платеж
C4: CPI, (RUB) | E4: СР | G4: Дифференцированный платеж
C5: PPI, (RUB) | E5: КР
C6: PPI, (USD)
C7: Индекс роста заработной платы (RUB)
C8: Индекс роста цен на естественные монополии (электроэнергия)
O127: ПЕРЕФОРМУЛИРОВАТЬ

Sheet Лист2
